<?xml version="1.0"?>
<robot xmlns:xacro="http://ros.org/wiki/xacro">

  <xacro:macro name="shooter_v0" params="parent *joint_origin">
        <joint name="shooter_shaft_link_joint" type="fixed">
          <xacro:insert_block name="joint_origin"/>
          <parent link="${parent}"/>
          <child link="shooter_base_link"/>
        </joint>

        <link name="shooter_base_link">
          <visual>
                <geometry>
                  <box size="0.2 0.18 0.08" />
                </geometry>
                <material name="gray"/>
          </visual>
          <collision>
                <geometry>
                  <box size="0.2 0.18 0.08" />
                </geometry>
          </collision>
          <inertial>
                <origin xyz="0 0 0"/>
                <mass value="1.0"/>
                <inertia ixx="0.1" ixy="0" ixz="0"
                                 iyy="0.1" iyz="0"
                                 izz="0.1" />
          </inertial>
        </link>

        <joint name="shooter_wall1_link_joint" type="fixed">
          <origin rpy="0 0 0" xyz="0.0 0.11 0.05"/>
          <parent link="shooter_base_link"/>
          <child link="shooter_wall1_link"/>
        </joint>

        <link name="shooter_wall1_link">
          <visual>
                <geometry>
                  <box size="0.2 0.02 0.08" />
                </geometry>
                <material name="gray"/>
          </visual>
          <collision>
                <geometry>
                  <box size="0.2 0.02 0.08" />
                </geometry>
          </collision>
          <inertial>
                <origin xyz="0 0 0"/>
                <mass value="1.0"/>
                <inertia ixx="0.1" ixy="0" ixz="0"
                                 iyy="0.1" iyz="0"
                                 izz="0.1" />
          </inertial>
        </link>

        <joint name="shooter_wall2_link_joint" type="fixed">
          <origin rpy="0 0 0" xyz="0.0 -0.11 0.05"/>
          <parent link="shooter_base_link"/>
          <child link="shooter_wall2_link"/>
        </joint>

        <link name="shooter_wall2_link">
          <visual>
                <geometry>
                  <box size="0.2 0.02 0.08" />
                </geometry>
                <material name="gray"/>
          </visual>
          <collision>
                <geometry>
                  <box size="0.2 0.02 0.08" />
                </geometry>
          </collision>
          <inertial>
                <origin xyz="0 0 0"/>
                <mass value="1.0"/>
                <inertia ixx="0.1" ixy="0" ixz="0"
                                 iyy="0.1" iyz="0"
                                 izz="0.1" />
          </inertial>
        </link>
                
        <joint name="shooter_pole1_link_joint" type="fixed">
          <origin rpy="0 0 0" xyz="0.07778 0.07778 0.315"/> <!-- disc pos x 0.18 z -0.0925 -->
          <parent link="shooter_base_link"/>
          <child link="shooter_pole1_link"/>
          <axis xyz="0 0 1"/>
        </joint>

        <link name="shooter_pole1_link">
          <visual>
                <geometry>
                  <cylinder length="0.5" radius="0.01" />
                </geometry>
                <material name="gray"/>
          </visual>
          <collision>
                <geometry>
                  <cylinder length="0.5" radius="0.01" />
                </geometry>
          </collision>
          <inertial>
                <origin xyz="0 0 0"/>
                <mass value="1.0"/>
                <inertia ixx="0.1" ixy="0" ixz="0"
                                 iyy="0.1" iyz="0"
                                 izz="0.1" />
          </inertial>
        </link>

        <joint name="shooter_pole2_link_joint" type="fixed">
          <origin rpy="0 0 0" xyz="-0.07778 0.07778 0.315"/> <!-- disc pos x 0.18 z -0.0925 -->
          <parent link="shooter_base_link"/>
          <child link="shooter_pole2_link"/>
          <axis xyz="0 0 1"/>
        </joint>

        <link name="shooter_pole2_link">
          <visual>
                <geometry>
                  <cylinder length="0.5" radius="0.01" />
                </geometry>
                <material name="gray"/>
          </visual>
          <collision>
                <geometry>
                  <cylinder length="0.5" radius="0.01" />
                </geometry>
          </collision>
          <inertial>
                <origin xyz="0 0 0"/>
                <mass value="1.0"/>
                <inertia ixx="0.1" ixy="0" ixz="0"
                                 iyy="0.1" iyz="0"
                                 izz="0.1" />
          </inertial>
        </link>

        <joint name="shooter_pole3_link_joint" type="fixed">
          <origin rpy="0 0 0" xyz="-0.07778 -0.07778 0.315"/> <!-- disc pos x 0.18 z -0.0925 -->
          <parent link="shooter_base_link"/>
          <child link="shooter_pole3_link"/>
          <axis xyz="0 0 1"/>
        </joint>

        <link name="shooter_pole3_link">
          <visual>
                <geometry>
                  <cylinder length="0.5" radius="0.01" />
                </geometry>
                <material name="gray"/>
          </visual>
          <collision>
                <geometry>
                  <cylinder length="0.5" radius="0.01" />
                </geometry>
          </collision>
          <inertial>
                <origin xyz="0 0 0"/>
                <mass value="1.0"/>
                <inertia ixx="0.1" ixy="0" ixz="0"
                                 iyy="0.1" iyz="0"
                                 izz="0.1" />
          </inertial>
        </link>

        <joint name="shooter_pole4_link_joint" type="fixed">
          <origin rpy="0 0 0" xyz="0.07778 -0.07778 0.315"/> <!-- disc pos x 0.18 z -0.0925 -->
          <parent link="shooter_base_link"/>
          <child link="shooter_pole4_link"/>
          <axis xyz="0 0 1"/>
        </joint>

        <link name="shooter_pole4_link">
          <visual>
                <geometry>
                  <cylinder length="0.5" radius="0.01" />
                </geometry>
                <material name="gray"/>
          </visual>
          <collision>
                <geometry>
                  <cylinder length="0.5" radius="0.01" />
                </geometry>
          </collision>
          <inertial>
                <origin xyz="0 0 0"/>
                <mass value="1.0"/>
                <inertia ixx="0.1" ixy="0" ixz="0"
                                 iyy="0.1" iyz="0"
                                 izz="0.1" />
          </inertial>
        </link>

        <joint name="shooter_pole5_link_joint" type="fixed">
          <origin rpy="0 0 0" xyz="0.11 0.0 0.365"/> <!-- disc pos x 0.18 z -0.0925 -->
          <parent link="shooter_base_link"/>
          <child link="shooter_pole5_link"/>
          <axis xyz="0 0 1"/>
        </joint>

        <link name="shooter_pole5_link">
          <visual>
                <geometry>
                  <cylinder length="0.4" radius="0.01" />
                </geometry>
                <material name="gray"/>
          </visual>
          <collision>
                <geometry>
                  <cylinder length="0.4" radius="0.01" />
                </geometry>
          </collision>
          <inertial>
                <origin xyz="0 0 0"/>
                <mass value="1.0"/>
                <inertia ixx="0.1" ixy="0" ixz="0"
                                 iyy="0.1" iyz="0"
                                 izz="0.1" />
          </inertial>
        </link>

        <joint name="shooter_pole6_link_joint" type="fixed">
          <origin rpy="0 0 0" xyz="-0.11 0.0 0.315"/> <!-- disc pos x 0.18 z -0.0925 -->
          <parent link="shooter_base_link"/>
          <child link="shooter_pole6_link"/>
          <axis xyz="0 0 1"/>
        </joint>

        <link name="shooter_pole6_link">
          <visual>
                <geometry>
                  <cylinder length="0.5" radius="0.01" />
                </geometry>
                <material name="gray"/>
          </visual>
          <collision>
                <geometry>
                  <cylinder length="0.5" radius="0.01" />
                </geometry>
          </collision>
          <inertial>
                <origin xyz="0 0 0"/>
                <mass value="1.0"/>
                <inertia ixx="0.1" ixy="0" ixz="0"
                                 iyy="0.1" iyz="0"
                                 izz="0.1" />
          </inertial>
        </link>
        
        <joint name="shooter_pole7_link_joint" type="fixed">
          <origin rpy="0 0 0" xyz="0.0 0.11 0.315"/> <!-- disc pos x 0.18 z -0.0925 -->
          <parent link="shooter_base_link"/>
          <child link="shooter_pole7_link"/>
          <axis xyz="0 0 1"/>
        </joint>

        <link name="shooter_pole7_link">
          <visual>
                <geometry>
                  <cylinder length="0.5" radius="0.01" />
                </geometry>
                <material name="gray"/>
          </visual>
          <collision>
                <geometry>
                  <cylinder length="0.5" radius="0.01" />
                </geometry>
          </collision>
          <inertial>
                <origin xyz="0 0 0"/>
                <mass value="1.0"/>
                <inertia ixx="0.1" ixy="0" ixz="0"
                                 iyy="0.1" iyz="0"
                                 izz="0.1" />
          </inertial>
        </link>

        <joint name="shooter_pole8_link_joint" type="fixed">
          <origin rpy="0 0 0" xyz="0.0 -0.11 0.315"/> <!-- disc pos x 0.18 z -0.0925 -->
          <parent link="shooter_base_link"/>
          <child link="shooter_pole8_link"/>
          <axis xyz="0 0 1"/>
        </joint>

        <link name="shooter_pole8_link">
          <visual>
                <geometry>
                  <cylinder length="0.5" radius="0.01" />
                </geometry>
                <material name="gray"/>
          </visual>
          <collision>
                <geometry>
                  <cylinder length="0.5" radius="0.01" />
                </geometry>
          </collision>
          <inertial>
                <origin xyz="0 0 0"/>
                <mass value="1.0"/>
                <inertia ixx="0.1" ixy="0" ixz="0"
                                 iyy="0.1" iyz="0"
                                 izz="0.1" />
          </inertial>
        </link>
        
         <joint name="shooter_loader_link_joint" type="continuous">
          <origin rpy="0 0 0" xyz="-0.12 0 0.05"/>
          <parent link="shooter_base_link"/>
          <child link="shooter_loader_link"/>
          <axis xyz="0 0 1"/>
        </joint>

        <link name="shooter_loader_link">
          <visual>
            <origin rpy="0 0 0" xyz="-0.05 0 0.0"/>
                <geometry>
                  <box size="0.1 0.04 0.02" />
                </geometry>
                <material name="gray"/>
          </visual>
          <collision>
            <origin rpy="0 0 0" xyz="-0.05 0 0.0"/>
                <geometry>
                  <box size="0.1 0.04 0.02" />
                </geometry>
          </collision>
          <inertial>
                <origin xyz="0 0 0"/>
                <mass value="1.0"/>
                <inertia ixx="0.1" ixy="0" ixz="0"
                                 iyy="0.1" iyz="0"
                                 izz="0.1" />
          </inertial>
        </link>


         <joint name="shooter_wheel1_link_joint" type="continuous">
          <origin rpy="${-pi/2} 0 0" xyz="0.15 0 0.015"/> <!-- disc pos x 0.18 z -0.0925 -->
          <parent link="shooter_base_link"/>
          <child link="shooter_wheel1_link"/>
          <axis xyz="0 0 1"/>
        </joint>

        <link name="shooter_wheel1_link">
          <visual>
                <geometry>
                  <cylinder length="0.18" radius="0.04" />
                </geometry>
                <material name="gray"/>
          </visual>
          <collision>
                <geometry>
                  <cylinder length="0.18" radius="0.04" />
                </geometry>
          </collision>
          <inertial>
                <origin xyz="0 0 0"/>
                <mass value="1.0"/>
                <inertia ixx="0.1" ixy="0" ixz="0"
                                 iyy="0.1" iyz="0"
                                 izz="0.1" />
          </inertial>
        </link>

         <joint name="shooter_wheel2_link_joint" type="continuous">
          <origin rpy="${-pi/2} 0 0" xyz="0.15 0 0.105"/> <!-- disc pos x 0.18 z -0.0925 -->
          <parent link="shooter_base_link"/>
          <child link="shooter_wheel2_link"/>
          <axis xyz="0 0 -1"/>
        </joint>

        <link name="shooter_wheel2_link">
          <visual>
                <geometry>
                  <cylinder length="0.18" radius="0.04" />
                </geometry>
                <material name="gray"/>
          </visual>
          <collision>
                <geometry>
                  <cylinder length="0.18" radius="0.04" />
                </geometry>
          </collision>
          <inertial>
                <origin xyz="0 0 0"/>
                <mass value="1.0"/>
                <inertia ixx="0.1" ixy="0" ixz="0"
                                 iyy="0.1" iyz="0"
                                 izz="0.1" />
          </inertial>
        </link>

  </xacro:macro>

</robot>

